Workbook

Sheet BoM Sheet
A1: Beginning of Mission Announcements & Tracker
A2: SOK Delegation · Alerts update automatically from today's date · Handover overlap = days the outgoing and incoming staff are both in post (negative = vacancy gap)
A4: TOTAL | C4: ARRIVED | D4: DUE ≤ 14 DAYS | E4: DUE ≤ 30 DAYS | G4: UPCOMING / TBC | H4: NEXT ARRIVAL
A5: =COUNTA($B$9:$B$108) -> 22 | C5: =COUNTIF($G$9:$G$108,"Arrived") -> 18 | D5: =COUNTIF($G$9:$G$108,"Due ≤ 14 days") -> 1 | E5: =COUNTIF($G$9:$G$108,"Due ≤ 30 days") -> 0 | G5: =COUNTIF($G$9:$G$108,"Upcoming")&" / "&COUNTIF($G$9:$G$108,"Date TBC") -> 3 / 0 | H5: =IF(COUNTIF($E$9:$E$108,">="&TODAY())=0,"None scheduled",INDEX($B$9:$B$108,MATCH(_xlfn.MINIFS($E$9:$E$108,$E$9:$E$108,">="&TODAY()),$E$9:$E$108,0))&" · "&TEXT(_xlfn.MINIFS($E$9:$E$108,$E$9:$E$108,">="&TODAY()),"dd mmm yyyy")) -> Mr. Martin RYNES · 02 Nov 2026
A8: No. | B8: Name | C8: Position | D8: Replacing | E8: Arrival Date (BoM) | F8: Days to Go | G8: Status | H8: Predecessor's EoM | I8: Handover Overlap (days) | J8: Notes
A9: =IF(B9="","",COUNTA($B$9:B9)) -> 1 | B9: Mr. Christophe MBARAGA | C9: Finance & Administration Manager | D9: Pranvera Vokshi | E9: 46127 | F9: =IF(OR(B9="",E9=""),"",E9-TODAY()) -> -197 | G9: =IF(B9="","",IF(E9="","Date TBC",IF(E9<TODAY(),"Arrived",IF(E9-TODAY()<=14,"Due ≤ 14 days",IF(E9-TODAY()<=30,"Due ≤ 30 days","Upcoming"))))) -> Arrived | H9: =IF(OR(B9="",D9=""),"",IF(D9="New position","New position",IF(COUNTIF('EoM Sheet'!$B$9:$B$108,"*"&D9)=0,"Not on EoM list",IF(_xlfn.MAXIFS('EoM Sheet'!$E$9:$E$108,'EoM Sheet'!$B$9:$B$108,"*"&D9)=0,"Date TBC",_xlfn.MAXIFS('EoM Sheet'!$E$9:$E$108,'EoM Sheet'!$B$9:$B$108,"*"&D9))))) -> Date TBC | I9: =IF(AND(ISNUMBER(E9),ISNUMBER(H9)),H9-E9,"")
A10: =IF(B10="","",COUNTA($B$9:B10)) -> 2 | B10: Ms. Carmen Elena MARTINEZ ALVARADO | C10: Wathab Engineer | D10: Melisa RADHAKRISHNAN | E10: 46139 | F10: =IF(OR(B10="",E10=""),"",E10-TODAY()) -> -185 | G10: =IF(B10="","",IF(E10="","Date TBC",IF(E10<TODAY(),"Arrived",IF(E10-TODAY()<=14,"Due ≤ 14 days",IF(E10-TODAY()<=30,"Due ≤ 30 days","Upcoming"))))) -> Arrived | H10: =IF(OR(B10="",D10=""),"",IF(D10="New position","New position",IF(COUNTIF('EoM Sheet'!$B$9:$B$108,"*"&D10)=0,"Not on EoM list",IF(_xlfn.MAXIFS('EoM Sheet'!$E$9:$E$108,'EoM Sheet'!$B$9:$B$108,"*"&D10)=0,"Date TBC",_xlfn.MAXIFS('EoM Sheet'!$E$9:$E$108,'EoM Sheet'!$B$9:$B$108,"*"&D10))))) -> Date TBC | I10: =IF(AND(ISNUMBER(E10),ISNUMBER(H10)),H10-E10,"")
A11: =IF(B11="","",COUNTA($B$9:B11)) -> 3 | B11: Ms. Vanessa IARIA | C11: Protection Delegate | D11: Nantenaina Raherimanjato | E11: 46138 | F11: =IF(OR(B11="",E11=""),"",E11-TODAY()) -> -186 | G11: =IF(B11="","",IF(E11="","Date TBC",IF(E11<TODAY(),"Arrived",IF(E11-TODAY()<=14,"Due ≤ 14 days",IF(E11-TODAY()<=30,"Due ≤ 30 days","Upcoming"))))) -> Arrived | H11: =IF(OR(B11="",D11=""),"",IF(D11="New position","New position",IF(COUNTIF('EoM Sheet'!$B$9:$B$108,"*"&D11)=0,"Not on EoM list",IF(_xlfn.MAXIFS('EoM Sheet'!$E$9:$E$108,'EoM Sheet'!$B$9:$B$108,"*"&D11)=0,"Date TBC",_xlfn.MAXIFS('EoM Sheet'!$E$9:$E$108,'EoM Sheet'!$B$9:$B$108,"*"&D11))))) -> Date TBC | I11: =IF(AND(ISNUMBER(E11),ISNUMBER(H11)),H11-E11,"")
A12: =IF(B12="","",COUNTA($B$9:B12)) -> 4 | B12: Ms. Beata SKWARSKA-SÖNCHEN | C12: Head of Programs & Prevention | D12: Alexandre Formisano | E12: 46165 | F12: =IF(OR(B12="",E12=""),"",E12-TODAY()) -> -159 | G12: =IF(B12="","",IF(E12="","Date TBC",IF(E12<TODAY(),"Arrived",IF(E12-TODAY()<=14,"Due ≤ 14 days",IF(E12-TODAY()<=30,"Due ≤ 30 days","Upcoming"))))) -> Arrived | H12: =IF(OR(B12="",D12=""),"",IF(D12="New position","New position",IF(COUNTIF('EoM Sheet'!$B$9:$B$108,"*"&D12)=0,"Not on EoM list",IF(_xlfn.MAXIFS('EoM Sheet'!$E$9:$E$108,'EoM Sheet'!$B$9:$B$108,"*"&D12)=0,"Date TBC",_xlfn.MAXIFS('EoM Sheet'!$E$9:$E$108,'EoM Sheet'!$B$9:$B$108,"*"&D12))))) -> 46175 | I12: =IF(AND(ISNUMBER(E12),ISNUMBER(H12)),H12-E12,"") -> 10
A13: =IF(B13="","",COUNTA($B$9:B13)) -> 5 | B13: Mr. Eduardo Augusto NEVES | C13: Ecosec Delegate | D13: Hassan Suleiman SULEIMAN | E13: 46167 | F13: =IF(OR(B13="",E13=""),"",E13-TODAY()) -> -157 | G13: =IF(B13="","",IF(E13="","Date TBC",IF(E13<TODAY(),"Arrived",IF(E13-TODAY()<=14,"Due ≤ 14 days",IF(E13-TODAY()<=30,"Due ≤ 30 days","Upcoming"))))) -> Arrived | H13: =IF(OR(B13="",D13=""),"",IF(D13="New position","New position",IF(COUNTIF('EoM Sheet'!$B$9:$B$108,"*"&D13)=0,"Not on EoM list",IF(_xlfn.MAXIFS('EoM Sheet'!$E$9:$E$108,'EoM Sheet'!$B$9:$B$108,"*"&D13)=0,"Date TBC",_xlfn.MAXIFS('EoM Sheet'!$E$9:$E$108,'EoM Sheet'!$B$9:$B$108,"*"&D13))))) -> 46177 | I13: =IF(AND(ISNUMBER(E13),ISNUMBER(H13)),H13-E13,"") -> 10
A14: =IF(B14="","",COUNTA($B$9:B14)) -> 6 | B14: Mr. Kosimo Anthony Richard UKELE | C14: Protection Delegate | D14: Mohammed Toffic | E14: 46181 | F14: =IF(OR(B14="",E14=""),"",E14-TODAY()) -> -143 | G14: =IF(B14="","",IF(E14="","Date TBC",IF(E14<TODAY(),"Arrived",IF(E14-TODAY()<=14,"Due ≤ 14 days",IF(E14-TODAY()<=30,"Due ≤ 30 days","Upcoming"))))) -> Arrived | H14: =IF(OR(B14="",D14=""),"",IF(D14="New position","New position",IF(COUNTIF('EoM Sheet'!$B$9:$B$108,"*"&D14)=0,"Not on EoM list",IF(_xlfn.MAXIFS('EoM Sheet'!$E$9:$E$108,'EoM Sheet'!$B$9:$B$108,"*"&D14)=0,"Date TBC",_xlfn.MAXIFS('EoM Sheet'!$E$9:$E$108,'EoM Sheet'!$B$9:$B$108,"*"&D14))))) -> Date TBC | I14: =IF(AND(ISNUMBER(E14),ISNUMBER(H14)),H14-E14,"")
A15: =IF(B15="","",COUNTA($B$9:B15)) -> 7 | B15: Mr. Ronaldo RAMIREZ RODRIGUEZ | C15: Data & Analytics Manager | D15: Ei Ei Tun | E15: 46216 | F15: =IF(OR(B15="",E15=""),"",E15-TODAY()) -> -108 | G15: =IF(B15="","",IF(E15="","Date TBC",IF(E15<TODAY(),"Arrived",IF(E15-TODAY()<=14,"Due ≤ 14 days",IF(E15-TODAY()<=30,"Due ≤ 30 days","Upcoming"))))) -> Arrived | H15: =IF(OR(B15="",D15=""),"",IF(D15="New position","New position",IF(COUNTIF('EoM Sheet'!$B$9:$B$108,"*"&D15)=0,"Not on EoM list",IF(_xlfn.MAXIFS('EoM Sheet'!$E$9:$E$108,'EoM Sheet'!$B$9:$B$108,"*"&D15)=0,"Date TBC",_xlfn.MAXIFS('EoM Sheet'!$E$9:$E$108,'EoM Sheet'!$B$9:$B$108,"*"&D15))))) -> Date TBC | I15: =IF(AND(ISNUMBER(E15),ISNUMBER(H15)),H15-E15,"")
A16: =IF(B16="","",COUNTA($B$9:B16)) -> 8 | B16: Ms. Despoina SPANOUDI | C16: Protection Coordinator | D16: Marie-Genevieve Nightingale | E16: 46221 | F16: =IF(OR(B16="",E16=""),"",E16-TODAY()) -> -103 | G16: =IF(B16="","",IF(E16="","Date TBC",IF(E16<TODAY(),"Arrived",IF(E16-TODAY()<=14,"Due ≤ 14 days",IF(E16-TODAY()<=30,"Due ≤ 30 days","Upcoming"))))) -> Arrived | H16: =IF(OR(B16="",D16=""),"",IF(D16="New position","New position",IF(COUNTIF('EoM Sheet'!$B$9:$B$108,"*"&D16)=0,"Not on EoM list",IF(_xlfn.MAXIFS('EoM Sheet'!$E$9:$E$108,'EoM Sheet'!$B$9:$B$108,"*"&D16)=0,"Date TBC",_xlfn.MAXIFS('EoM Sheet'!$E$9:$E$108,'EoM Sheet'!$B$9:$B$108,"*"&D16))))) -> 46237 | I16: =IF(AND(ISNUMBER(E16),ISNUMBER(H16)),H16-E16,"") -> 16
A17: =IF(B17="","",COUNTA($B$9:B17)) -> 9 | B17: Mr. Chawki LAATAR | C17: Health Delegate North | D17: Hamed MAHAMAT TAHER HAROUNA | E17: 46223 | F17: =IF(OR(B17="",E17=""),"",E17-TODAY()) -> -101 | G17: =IF(B17="","",IF(E17="","Date TBC",IF(E17<TODAY(),"Arrived",IF(E17-TODAY()<=14,"Due ≤ 14 days",IF(E17-TODAY()<=30,"Due ≤ 30 days","Upcoming"))))) -> Arrived | H17: =IF(OR(B17="",D17=""),"",IF(D17="New position","New position",IF(COUNTIF('EoM Sheet'!$B$9:$B$108,"*"&D17)=0,"Not on EoM list",IF(_xlfn.MAXIFS('EoM Sheet'!$E$9:$E$108,'EoM Sheet'!$B$9:$B$108,"*"&D17)=0,"Date TBC",_xlfn.MAXIFS('EoM Sheet'!$E$9:$E$108,'EoM Sheet'!$B$9:$B$108,"*"&D17))))) -> 46232 | I17: =IF(AND(ISNUMBER(E17),ISNUMBER(H17)),H17-E17,"") -> 9
A18: =IF(B18="","",COUNTA($B$9:B18)) -> 10 | B18: Mr. Andrew MOK YUAN MIN | C18: First Aid and Prehospital Emergency Care Delegate | D18: Mickael PAYET | E18: 46228 | F18: =IF(OR(B18="",E18=""),"",E18-TODAY()) -> -96 | G18: =IF(B18="","",IF(E18="","Date TBC",IF(E18<TODAY(),"Arrived",IF(E18-TODAY()<=14,"Due ≤ 14 days",IF(E18-TODAY()<=30,"Due ≤ 30 days","Upcoming"))))) -> Arrived | H18: =IF(OR(B18="",D18=""),"",IF(D18="New position","New position",IF(COUNTIF('EoM Sheet'!$B$9:$B$108,"*"&D18)=0,"Not on EoM list",IF(_xlfn.MAXIFS('EoM Sheet'!$E$9:$E$108,'EoM Sheet'!$B$9:$B$108,"*"&D18)=0,"Date TBC",_xlfn.MAXIFS('EoM Sheet'!$E$9:$E$108,'EoM Sheet'!$B$9:$B$108,"*"&D18))))) -> 46234 | I18: =IF(AND(ISNUMBER(E18),ISNUMBER(H18)),H18-E18,"") -> 6
A19: =IF(B19="","",COUNTA($B$9:B19)) -> 11 | B19: Ms. Cornelia Isabella HEINE | C19: Economic Security Delegate | D19: Mari Fungirayi MANYARARA | E19: 46257 | F19: =IF(OR(B19="",E19=""),"",E19-TODAY()) -> -67 | G19: =IF(B19="","",IF(E19="","Date TBC",IF(E19<TODAY(),"Arrived",IF(E19-TODAY()<=14,"Due ≤ 14 days",IF(E19-TODAY()<=30,"Due ≤ 30 days","Upcoming"))))) -> Arrived | H19: =IF(OR(B19="",D19=""),"",IF(D19="New position","New position",IF(COUNTIF('EoM Sheet'!$B$9:$B$108,"*"&D19)=0,"Not on EoM list",IF(_xlfn.MAXIFS('EoM Sheet'!$E$9:$E$108,'EoM Sheet'!$B$9:$B$108,"*"&D19)=0,"Date TBC",_xlfn.MAXIFS('EoM Sheet'!$E$9:$E$108,'EoM Sheet'!$B$9:$B$108,"*"&D19))))) -> 46257 | I19: =IF(AND(ISNUMBER(E19),ISNUMBER(H19)),H19-E19,"") -> 0
A20: =IF(B20="","",COUNTA($B$9:B20)) -> 12 | B20: Mr. Subhash SINHA | C20: Physical Rehabilitation Project Manager | D20: Philip MORGAN | E20: 46236 | F20: =IF(OR(B20="",E20=""),"",E20-TODAY()) -> -88 | G20: =IF(B20="","",IF(E20="","Date TBC",IF(E20<TODAY(),"Arrived",IF(E20-TODAY()<=14,"Due ≤ 14 days",IF(E20-TODAY()<=30,"Due ≤ 30 days","Upcoming"))))) -> Arrived | H20: =IF(OR(B20="",D20=""),"",IF(D20="New position","New position",IF(COUNTIF('EoM Sheet'!$B$9:$B$108,"*"&D20)=0,"Not on EoM list",IF(_xlfn.MAXIFS('EoM Sheet'!$E$9:$E$108,'EoM Sheet'!$B$9:$B$108,"*"&D20)=0,"Date TBC",_xlfn.MAXIFS('EoM Sheet'!$E$9:$E$108,'EoM Sheet'!$B$9:$B$108,"*"&D20))))) -> Date TBC | I20: =IF(AND(ISNUMBER(E20),ISNUMBER(H20)),H20-E20,"")
... A30: =IF(B30="","",COUNTA($B$9:B30)) -> 22 | B30: Mr. Zeljko LEZAJA | C30: Head Of Sub Structure 3 | D30: Manish DAS | E30: 46371 | F30: =IF(OR(B30="",E30=""),"",E30-TODAY()) -> 47 | G30: =IF(B30="","",IF(E30="","Date TBC",IF(E30<TODAY(),"Arrived",IF(E30-TODAY()<=14,"Due ≤ 14 days",IF(E30-TODAY()<=30,"Due ≤ 30 days","Upcoming"))))) -> Upcoming | H30: =IF(OR(B30="",D30=""),"",IF(D30="New position","New position",IF(COUNTIF('EoM Sheet'!$B$9:$B$108,"*"&D30)=0,"Not on EoM list",IF(_xlfn.MAXIFS('EoM Sheet'!$E$9:$E$108,'EoM Sheet'!$B$9:$B$108,"*"&D30)=0,"Date TBC",_xlfn.MAXIFS('EoM Sheet'!$E$9:$E$108,'EoM Sheet'!$B$9:$B$108,"*"&D30))))) -> Not on EoM list | I30: =IF(AND(ISNUMBER(E30),ISNUMBER(H30)),H30-E30,"")
A31: =IF(B31="","",COUNTA($B$9:B31)) | F31: =IF(OR(B31="",E31=""),"",E31-TODAY()) | G31: =IF(B31="","",IF(E31="","Date TBC",IF(E31<TODAY(),"Arrived",IF(E31-TODAY()<=14,"Due ≤ 14 days",IF(E31-TODAY()<=30,"Due ≤ 30 days","Upcoming"))))) | H31: =IF(OR(B31="",D31=""),"",IF(D31="New position","New position",IF(COUNTIF('EoM Sheet'!$B$9:$B$108,"*"&D31)=0,"Not on EoM list",IF(_xlfn.MAXIFS('EoM Sheet'!$E$9:$E$108,'EoM Sheet'!$B$9:$B$108,"*"&D31)=0,"Date TBC",_xlfn.MAXIFS('EoM Sheet'!$E$9:$E$108,'EoM Sheet'!$B$9:$B$108,"*"&D31))))) | I31: =IF(AND(ISNUMBER(E31),ISNUMBER(H31)),H31-E31,"")
A32: =IF(B32="","",COUNTA($B$9:B32)) | F32: =IF(OR(B32="",E32=""),"",E32-TODAY()) | G32: =IF(B32="","",IF(E32="","Date TBC",IF(E32<TODAY(),"Arrived",IF(E32-TODAY()<=14,"Due ≤ 14 days",IF(E32-TODAY()<=30,"Due ≤ 30 days","Upcoming"))))) | H32: =IF(OR(B32="",D32=""),"",IF(D32="New position","New position",IF(COUNTIF('EoM Sheet'!$B$9:$B$108,"*"&D32)=0,"Not on EoM list",IF(_xlfn.MAXIFS('EoM Sheet'!$E$9:$E$108,'EoM Sheet'!$B$9:$B$108,"*"&D32)=0,"Date TBC",_xlfn.MAXIFS('EoM Sheet'!$E$9:$E$108,'EoM Sheet'!$B$9:$B$108,"*"&D32))))) | I32: =IF(AND(ISNUMBER(E32),ISNUMBER(H32)),H32-E32,"")
A33: =IF(B33="","",COUNTA($B$9:B33)) | F33: =IF(OR(B33="",E33=""),"",E33-TODAY()) | G33: =IF(B33="","",IF(E33="","Date TBC",IF(E33<TODAY(),"Arrived",IF(E33-TODAY()<=14,"Due ≤ 14 days",IF(E33-TODAY()<=30,"Due ≤ 30 days","Upcoming"))))) | H33: =IF(OR(B33="",D33=""),"",IF(D33="New position","New position",IF(COUNTIF('EoM Sheet'!$B$9:$B$108,"*"&D33)=0,"Not on EoM list",IF(_xlfn.MAXIFS('EoM Sheet'!$E$9:$E$108,'EoM Sheet'!$B$9:$B$108,"*"&D33)=0,"Date TBC",_xlfn.MAXIFS('EoM Sheet'!$E$9:$E$108,'EoM Sheet'!$B$9:$B$108,"*"&D33))))) | I33: =IF(AND(ISNUMBER(E33),ISNUMBER(H33)),H33-E33,"")
A34: =IF(B34="","",COUNTA($B$9:B34)) | F34: =IF(OR(B34="",E34=""),"",E34-TODAY()) | G34: =IF(B34="","",IF(E34="","Date TBC",IF(E34<TODAY(),"Arrived",IF(E34-TODAY()<=14,"Due ≤ 14 days",IF(E34-TODAY()<=30,"Due ≤ 30 days","Upcoming"))))) | H34: =IF(OR(B34="",D34=""),"",IF(D34="New position","New position",IF(COUNTIF('EoM Sheet'!$B$9:$B$108,"*"&D34)=0,"Not on EoM list",IF(_xlfn.MAXIFS('EoM Sheet'!$E$9:$E$108,'EoM Sheet'!$B$9:$B$108,"*"&D34)=0,"Date TBC",_xlfn.MAXIFS('EoM Sheet'!$E$9:$E$108,'EoM Sheet'!$B$9:$B$108,"*"&D34))))) | I34: =IF(AND(ISNUMBER(E34),ISNUMBER(H34)),H34-E34,"")
A35: =IF(B35="","",COUNTA($B$9:B35)) | F35: =IF(OR(B35="",E35=""),"",E35-TODAY()) | G35: =IF(B35="","",IF(E35="","Date TBC",IF(E35<TODAY(),"Arrived",IF(E35-TODAY()<=14,"Due ≤ 14 days",IF(E35-TODAY()<=30,"Due ≤ 30 days","Upcoming"))))) | H35: =IF(OR(B35="",D35=""),"",IF(D35="New position","New position",IF(COUNTIF('EoM Sheet'!$B$9:$B$108,"*"&D35)=0,"Not on EoM list",IF(_xlfn.MAXIFS('EoM Sheet'!$E$9:$E$108,'EoM Sheet'!$B$9:$B$108,"*"&D35)=0,"Date TBC",_xlfn.MAXIFS('EoM Sheet'!$E$9:$E$108,'EoM Sheet'!$B$9:$B$108,"*"&D35))))) | I35: =IF(AND(ISNUMBER(E35),ISNUMBER(H35)),H35-E35,"")
A36: =IF(B36="","",COUNTA($B$9:B36)) | F36: =IF(OR(B36="",E36=""),"",E36-TODAY()) | G36: =IF(B36="","",IF(E36="","Date TBC",IF(E36<TODAY(),"Arrived",IF(E36-TODAY()<=14,"Due ≤ 14 days",IF(E36-TODAY()<=30,"Due ≤ 30 days","Upcoming"))))) | H36: =IF(OR(B36="",D36=""),"",IF(D36="New position","New position",IF(COUNTIF('EoM Sheet'!$B$9:$B$108,"*"&D36)=0,"Not on EoM list",IF(_xlfn.MAXIFS('EoM Sheet'!$E$9:$E$108,'EoM Sheet'!$B$9:$B$108,"*"&D36)=0,"Date TBC",_xlfn.MAXIFS('EoM Sheet'!$E$9:$E$108,'EoM Sheet'!$B$9:$B$108,"*"&D36))))) | I36: =IF(AND(ISNUMBER(E36),ISNUMBER(H36)),H36-E36,"")
A37: =IF(B37="","",COUNTA($B$9:B37)) | F37: =IF(OR(B37="",E37=""),"",E37-TODAY()) | G37: =IF(B37="","",IF(E37="","Date TBC",IF(E37<TODAY(),"Arrived",IF(E37-TODAY()<=14,"Due ≤ 14 days",IF(E37-TODAY()<=30,"Due ≤ 30 days","Upcoming"))))) | H37: =IF(OR(B37="",D37=""),"",IF(D37="New position","New position",IF(COUNTIF('EoM Sheet'!$B$9:$B$108,"*"&D37)=0,"Not on EoM list",IF(_xlfn.MAXIFS('EoM Sheet'!$E$9:$E$108,'EoM Sheet'!$B$9:$B$108,"*"&D37)=0,"Date TBC",_xlfn.MAXIFS('EoM Sheet'!$E$9:$E$108,'EoM Sheet'!$B$9:$B$108,"*"&D37))))) | I37: =IF(AND(ISNUMBER(E37),ISNUMBER(H37)),H37-E37,"")
A38: =IF(B38="","",COUNTA($B$9:B38)) | F38: =IF(OR(B38="",E38=""),"",E38-TODAY()) | G38: =IF(B38="","",IF(E38="","Date TBC",IF(E38<TODAY(),"Arrived",IF(E38-TODAY()<=14,"Due ≤ 14 days",IF(E38-TODAY()<=30,"Due ≤ 30 days","Upcoming"))))) | H38: =IF(OR(B38="",D38=""),"",IF(D38="New position","New position",IF(COUNTIF('EoM Sheet'!$B$9:$B$108,"*"&D38)=0,"Not on EoM list",IF(_xlfn.MAXIFS('EoM Sheet'!$E$9:$E$108,'EoM Sheet'!$B$9:$B$108,"*"&D38)=0,"Date TBC",_xlfn.MAXIFS('EoM Sheet'!$E$9:$E$108,'EoM Sheet'!$B$9:$B$108,"*"&D38))))) | I38: =IF(AND(ISNUMBER(E38),ISNUMBER(H38)),H38-E38,"")
A39: =IF(B39="","",COUNTA($B$9:B39)) | F39: =IF(OR(B39="",E39=""),"",E39-TODAY()) | G39: =IF(B39="","",IF(E39="","Date TBC",IF(E39<TODAY(),"Arrived",IF(E39-TODAY()<=14,"Due ≤ 14 days",IF(E39-TODAY()<=30,"Due ≤ 30 days","Upcoming"))))) | H39: =IF(OR(B39="",D39=""),"",IF(D39="New position","New position",IF(COUNTIF('EoM Sheet'!$B$9:$B$108,"*"&D39)=0,"Not on EoM list",IF(_xlfn.MAXIFS('EoM Sheet'!$E$9:$E$108,'EoM Sheet'!$B$9:$B$108,"*"&D39)=0,"Date TBC",_xlfn.MAXIFS('EoM Sheet'!$E$9:$E$108,'EoM Sheet'!$B$9:$B$108,"*"&D39))))) | I39: =IF(AND(ISNUMBER(E39),ISNUMBER(H39)),H39-E39,"")
A40: =IF(B40="","",COUNTA($B$9:B40)) | F40: =IF(OR(B40="",E40=""),"",E40-TODAY()) | G40: =IF(B40="","",IF(E40="","Date TBC",IF(E40<TODAY(),"Arrived",IF(E40-TODAY()<=14,"Due ≤ 14 days",IF(E40-TODAY()<=30,"Due ≤ 30 days","Upcoming"))))) | H40: =IF(OR(B40="",D40=""),"",IF(D40="New position","New position",IF(COUNTIF('EoM Sheet'!$B$9:$B$108,"*"&D40)=0,"Not on EoM list",IF(_xlfn.MAXIFS('EoM Sheet'!$E$9:$E$108,'EoM Sheet'!$B$9:$B$108,"*"&D40)=0,"Date TBC",_xlfn.MAXIFS('EoM Sheet'!$E$9:$E$108,'EoM Sheet'!$B$9:$B$108,"*"&D40))))) | I40: =IF(AND(ISNUMBER(E40),ISNUMBER(H40)),H40-E40,"")
A41: =IF(B41="","",COUNTA($B$9:B41)) | F41: =IF(OR(B41="",E41=""),"",E41-TODAY()) | G41: =IF(B41="","",IF(E41="","Date TBC",IF(E41<TODAY(),"Arrived",IF(E41-TODAY()<=14,"Due ≤ 14 days",IF(E41-TODAY()<=30,"Due ≤ 30 days","Upcoming"))))) | H41: =IF(OR(B41="",D41=""),"",IF(D41="New position","New position",IF(COUNTIF('EoM Sheet'!$B$9:$B$108,"*"&D41)=0,"Not on EoM list",IF(_xlfn.MAXIFS('EoM Sheet'!$E$9:$E$108,'EoM Sheet'!$B$9:$B$108,"*"&D41)=0,"Date TBC",_xlfn.MAXIFS('EoM Sheet'!$E$9:$E$108,'EoM Sheet'!$B$9:$B$108,"*"&D41))))) | I41: =IF(AND(ISNUMBER(E41),ISNUMBER(H41)),H41-E41,"")
A42: =IF(B42="","",COUNTA($B$9:B42)) | F42: =IF(OR(B42="",E42=""),"",E42-TODAY()) | G42: =IF(B42="","",IF(E42="","Date TBC",IF(E42<TODAY(),"Arrived",IF(E42-TODAY()<=14,"Due ≤ 14 days",IF(E42-TODAY()<=30,"Due ≤ 30 days","Upcoming"))))) | H42: =IF(OR(B42="",D42=""),"",IF(D42="New position","New position",IF(COUNTIF('EoM Sheet'!$B$9:$B$108,"*"&D42)=0,"Not on EoM list",IF(_xlfn.MAXIFS('EoM Sheet'!$E$9:$E$108,'EoM Sheet'!$B$9:$B$108,"*"&D42)=0,"Date TBC",_xlfn.MAXIFS('EoM Sheet'!$E$9:$E$108,'EoM Sheet'!$B$9:$B$108,"*"&D42))))) | I42: =IF(AND(ISNUMBER(E42),ISNUMBER(H42)),H42-E42,"")
... A108: =IF(B108="","",COUNTA($B$9:B108)) | F108: =IF(OR(B108="",E108=""),"",E108-TODAY()) | G108: =IF(B108="","",IF(E108="","Date TBC",IF(E108<TODAY(),"Arrived",IF(E108-TODAY()<=14,"Due ≤ 14 days",IF(E108-TODAY()<=30,"Due ≤ 30 days","Upcoming"))))) | H108: =IF(OR(B108="",D108=""),"",IF(D108="New position","New position",IF(COUNTIF('EoM Sheet'!$B$9:$B$108,"*"&D108)=0,"Not on EoM list",IF(_xlfn.MAXIFS('EoM Sheet'!$E$9:$E$108,'EoM Sheet'!$B$9:$B$108,"*"&D108)=0,"Date TBC",_xlfn.MAXIFS('EoM Sheet'!$E$9:$E$108,'EoM Sheet'!$B$9:$B$108,"*"&D108))))) | I108: =IF(AND(ISNUMBER(E108),ISNUMBER(H108)),H108-E108,"")
B110: Status key
B111: Arrived | C111: Date has passed
B112: Due ≤ 14 days | C112: Within the next two weeks — action needed
B113: Due ≤ 30 days | C113: Within the next month
B114: Upcoming | C114: More than 30 days away
B115: Date TBC | C115: No date entered yet
B117: Highlighted name (amber) = the same person appears twice on this sheet.

Sheet EoM Sheet
A1: End of Mission Tracker
A2: SOK Delegation · Alerts update automatically from today's date · Handover overlap = days the outgoing and incoming staff are both in post (negative = vacancy gap)
A4: TOTAL | C4: DEPARTED | D4: DUE ≤ 14 DAYS | E4: DUE ≤ 30 DAYS | G4: UPCOMING / TBC | H4: NEXT DEPARTURE
A5: =COUNTA($B$9:$B$108) -> 23 | C5: =COUNTIF($G$9:$G$108,"Departed") -> 10 | D5: =COUNTIF($G$9:$G$108,"Due ≤ 14 days") -> 1 | E5: =COUNTIF($G$9:$G$108,"Due ≤ 30 days") -> 0 | G5: =COUNTIF($G$9:$G$108,"Upcoming")&" / "&COUNTIF($G$9:$G$108,"Date TBC") -> 4 / 8 | H5: =IF(COUNTIF($E$9:$E$108,">="&TODAY())=0,"None scheduled",INDEX($B$9:$B$108,MATCH(_xlfn.MINIFS($E$9:$E$108,$E$9:$E$108,">="&TODAY()),$E$9:$E$108,0))&" · "&TEXT(_xlfn.MINIFS($E$9:$E$108,$E$9:$E$108,">="&TODAY()),"dd mmm yyyy")) -> Fernando Ivan SANTOS OSTROWSKI · 02 Nov 2026
A8: No. | B8: Name | C8: Position | D8: Replacement | E8: Departure Date (EoM) | F8: Days to Go | G8: Status | H8: Replacement's BoM | I8: Handover Overlap (days) | J8: Notes
A9: =IF(B9="","",COUNTA($B$9:B9)) -> 1 | B9: Marie-Genevieve Nightingale | C9: Protection Coordinator | D9: Ms. Despoina SPANOUDI | E9: 46237 | F9: =IF(OR(B9="",E9=""),"",E9-TODAY()) -> -87 | G9: =IF(B9="","",IF(E9="","Date TBC",IF(E9<TODAY(),"Departed",IF(E9-TODAY()<=14,"Due ≤ 14 days",IF(E9-TODAY()<=30,"Due ≤ 30 days","Upcoming"))))) -> Departed | H9: =IF(OR(B9="",D9=""),"",IF(D9="New position","New position",IF(COUNTIF('BoM Sheet'!$B$9:$B$108,"*"&D9)=0,"Not on BoM list",IF(_xlfn.MAXIFS('BoM Sheet'!$E$9:$E$108,'BoM Sheet'!$B$9:$B$108,"*"&D9)=0,"Date TBC",_xlfn.MAXIFS('BoM Sheet'!$E$9:$E$108,'BoM Sheet'!$B$9:$B$108,"*"&D9))))) -> 46221 | I9: =IF(AND(ISNUMBER(E9),ISNUMBER(H9)),E9-H9,"") -> 16
A10: =IF(B10="","",COUNTA($B$9:B10)) -> 2 | B10: Alexandre Formisano | C10: Head of Programs & Prevention | D10: Ms. Beata SKWARSKA-SÖNCHEN | E10: 46175 | F10: =IF(OR(B10="",E10=""),"",E10-TODAY()) -> -149 | G10: =IF(B10="","",IF(E10="","Date TBC",IF(E10<TODAY(),"Departed",IF(E10-TODAY()<=14,"Due ≤ 14 days",IF(E10-TODAY()<=30,"Due ≤ 30 days","Upcoming"))))) -> Departed | H10: =IF(OR(B10="",D10=""),"",IF(D10="New position","New position",IF(COUNTIF('BoM Sheet'!$B$9:$B$108,"*"&D10)=0,"Not on BoM list",IF(_xlfn.MAXIFS('BoM Sheet'!$E$9:$E$108,'BoM Sheet'!$B$9:$B$108,"*"&D10)=0,"Date TBC",_xlfn.MAXIFS('BoM Sheet'!$E$9:$E$108,'BoM Sheet'!$B$9:$B$108,"*"&D10))))) -> 46165 | I10: =IF(AND(ISNUMBER(E10),ISNUMBER(H10)),E10-H10,"") -> 10
A11: =IF(B11="","",COUNTA($B$9:B11)) -> 3 | B11: Hossein Javadian | C11: Country Procurement Manager | D11: Ms. Asvat AKHMEDOVA | F11: =IF(OR(B11="",E11=""),"",E11-TODAY()) | G11: =IF(B11="","",IF(E11="","Date TBC",IF(E11<TODAY(),"Departed",IF(E11-TODAY()<=14,"Due ≤ 14 days",IF(E11-TODAY()<=30,"Due ≤ 30 days","Upcoming"))))) -> Date TBC | H11: =IF(OR(B11="",D11=""),"",IF(D11="New position","New position",IF(COUNTIF('BoM Sheet'!$B$9:$B$108,"*"&D11)=0,"Not on BoM list",IF(_xlfn.MAXIFS('BoM Sheet'!$E$9:$E$108,'BoM Sheet'!$B$9:$B$108,"*"&D11)=0,"Date TBC",_xlfn.MAXIFS('BoM Sheet'!$E$9:$E$108,'BoM Sheet'!$B$9:$B$108,"*"&D11))))) -> 46313 | I11: =IF(AND(ISNUMBER(E11),ISNUMBER(H11)),E11-H11,"")
A12: =IF(B12="","",COUNTA($B$9:B12)) -> 4 | B12: Philip MORGAN | C12: Physical Rehabilitation Project Manager | D12: Mr. Subhash SINHA | F12: =IF(OR(B12="",E12=""),"",E12-TODAY()) | G12: =IF(B12="","",IF(E12="","Date TBC",IF(E12<TODAY(),"Departed",IF(E12-TODAY()<=14,"Due ≤ 14 days",IF(E12-TODAY()<=30,"Due ≤ 30 days","Upcoming"))))) -> Date TBC | H12: =IF(OR(B12="",D12=""),"",IF(D12="New position","New position",IF(COUNTIF('BoM Sheet'!$B$9:$B$108,"*"&D12)=0,"Not on BoM list",IF(_xlfn.MAXIFS('BoM Sheet'!$E$9:$E$108,'BoM Sheet'!$B$9:$B$108,"*"&D12)=0,"Date TBC",_xlfn.MAXIFS('BoM Sheet'!$E$9:$E$108,'BoM Sheet'!$B$9:$B$108,"*"&D12))))) -> 46236 | I12: =IF(AND(ISNUMBER(E12),ISNUMBER(H12)),E12-H12,"")
A13: =IF(B13="","",COUNTA($B$9:B13)) -> 5 | B13: Nantenaina Raherimanjato | C13: Protection Delegate | D13: Ms. Vanessa IARIA | F13: =IF(OR(B13="",E13=""),"",E13-TODAY()) | G13: =IF(B13="","",IF(E13="","Date TBC",IF(E13<TODAY(),"Departed",IF(E13-TODAY()<=14,"Due ≤ 14 days",IF(E13-TODAY()<=30,"Due ≤ 30 days","Upcoming"))))) -> Date TBC | H13: =IF(OR(B13="",D13=""),"",IF(D13="New position","New position",IF(COUNTIF('BoM Sheet'!$B$9:$B$108,"*"&D13)=0,"Not on BoM list",IF(_xlfn.MAXIFS('BoM Sheet'!$E$9:$E$108,'BoM Sheet'!$B$9:$B$108,"*"&D13)=0,"Date TBC",_xlfn.MAXIFS('BoM Sheet'!$E$9:$E$108,'BoM Sheet'!$B$9:$B$108,"*"&D13))))) -> 46138 | I13: =IF(AND(ISNUMBER(E13),ISNUMBER(H13)),E13-H13,"")
A14: =IF(B14="","",COUNTA($B$9:B14)) -> 6 | B14: Pranvera Vokshi | C14: Finance & Administration Manager | D14: Mr. Christophe MBARAGA | F14: =IF(OR(B14="",E14=""),"",E14-TODAY()) | G14: =IF(B14="","",IF(E14="","Date TBC",IF(E14<TODAY(),"Departed",IF(E14-TODAY()<=14,"Due ≤ 14 days",IF(E14-TODAY()<=30,"Due ≤ 30 days","Upcoming"))))) -> Date TBC | H14: =IF(OR(B14="",D14=""),"",IF(D14="New position","New position",IF(COUNTIF('BoM Sheet'!$B$9:$B$108,"*"&D14)=0,"Not on BoM list",IF(_xlfn.MAXIFS('BoM Sheet'!$E$9:$E$108,'BoM Sheet'!$B$9:$B$108,"*"&D14)=0,"Date TBC",_xlfn.MAXIFS('BoM Sheet'!$E$9:$E$108,'BoM Sheet'!$B$9:$B$108,"*"&D14))))) -> 46127 | I14: =IF(AND(ISNUMBER(E14),ISNUMBER(H14)),E14-H14,"")
A15: =IF(B15="","",COUNTA($B$9:B15)) -> 7 | B15: Seunghyeon HAN | C15: Deputy Wathab Coordinator | D15: Mr. Julien BERDA | F15: =IF(OR(B15="",E15=""),"",E15-TODAY()) | G15: =IF(B15="","",IF(E15="","Date TBC",IF(E15<TODAY(),"Departed",IF(E15-TODAY()<=14,"Due ≤ 14 days",IF(E15-TODAY()<=30,"Due ≤ 30 days","Upcoming"))))) -> Date TBC | H15: =IF(OR(B15="",D15=""),"",IF(D15="New position","New position",IF(COUNTIF('BoM Sheet'!$B$9:$B$108,"*"&D15)=0,"Not on BoM list",IF(_xlfn.MAXIFS('BoM Sheet'!$E$9:$E$108,'BoM Sheet'!$B$9:$B$108,"*"&D15)=0,"Date TBC",_xlfn.MAXIFS('BoM Sheet'!$E$9:$E$108,'BoM Sheet'!$B$9:$B$108,"*"&D15))))) -> 46266 | I15: =IF(AND(ISNUMBER(E15),ISNUMBER(H15)),E15-H15,"")
A16: =IF(B16="","",COUNTA($B$9:B16)) -> 8 | B16: Melisa RADHAKRISHNAN | C16: Wathab Engineer | D16: Ms. Carmen Elena MARTINEZ ALVARADO | F16: =IF(OR(B16="",E16=""),"",E16-TODAY()) | G16: =IF(B16="","",IF(E16="","Date TBC",IF(E16<TODAY(),"Departed",IF(E16-TODAY()<=14,"Due ≤ 14 days",IF(E16-TODAY()<=30,"Due ≤ 30 days","Upcoming"))))) -> Date TBC | H16: =IF(OR(B16="",D16=""),"",IF(D16="New position","New position",IF(COUNTIF('BoM Sheet'!$B$9:$B$108,"*"&D16)=0,"Not on BoM list",IF(_xlfn.MAXIFS('BoM Sheet'!$E$9:$E$108,'BoM Sheet'!$B$9:$B$108,"*"&D16)=0,"Date TBC",_xlfn.MAXIFS('BoM Sheet'!$E$9:$E$108,'BoM Sheet'!$B$9:$B$108,"*"&D16))))) -> 46139 | I16: =IF(AND(ISNUMBER(E16),ISNUMBER(H16)),E16-H16,"")
A17: =IF(B17="","",COUNTA($B$9:B17)) -> 9 | B17: Hassan Suleiman SULEIMAN | C17: Ecosec Delegate | D17: Mr. Eduardo Augusto NEVES | E17: 46177 | F17: =IF(OR(B17="",E17=""),"",E17-TODAY()) -> -147 | G17: =IF(B17="","",IF(E17="","Date TBC",IF(E17<TODAY(),"Departed",IF(E17-TODAY()<=14,"Due ≤ 14 days",IF(E17-TODAY()<=30,"Due ≤ 30 days","Upcoming"))))) -> Departed | H17: =IF(OR(B17="",D17=""),"",IF(D17="New position","New position",IF(COUNTIF('BoM Sheet'!$B$9:$B$108,"*"&D17)=0,"Not on BoM list",IF(_xlfn.MAXIFS('BoM Sheet'!$E$9:$E$108,'BoM Sheet'!$B$9:$B$108,"*"&D17)=0,"Date TBC",_xlfn.MAXIFS('BoM Sheet'!$E$9:$E$108,'BoM Sheet'!$B$9:$B$108,"*"&D17))))) -> 46167 | I17: =IF(AND(ISNUMBER(E17),ISNUMBER(H17)),E17-H17,"") -> 10
A18: =IF(B18="","",COUNTA($B$9:B18)) -> 10 | B18: Mohammed Toffic | C18: Protection Delegate | D18: Mr. Kosimo Anthony Richard UKELE | F18: =IF(OR(B18="",E18=""),"",E18-TODAY()) | G18: =IF(B18="","",IF(E18="","Date TBC",IF(E18<TODAY(),"Departed",IF(E18-TODAY()<=14,"Due ≤ 14 days",IF(E18-TODAY()<=30,"Due ≤ 30 days","Upcoming"))))) -> Date TBC | H18: =IF(OR(B18="",D18=""),"",IF(D18="New position","New position",IF(COUNTIF('BoM Sheet'!$B$9:$B$108,"*"&D18)=0,"Not on BoM list",IF(_xlfn.MAXIFS('BoM Sheet'!$E$9:$E$108,'BoM Sheet'!$B$9:$B$108,"*"&D18)=0,"Date TBC",_xlfn.MAXIFS('BoM Sheet'!$E$9:$E$108,'BoM Sheet'!$B$9:$B$108,"*"&D18))))) -> 46181 | I18: =IF(AND(ISNUMBER(E18),ISNUMBER(H18)),E18-H18,"")
A19: =IF(B19="","",COUNTA($B$9:B19)) -> 11 | B19: Ei Ei Tun | C19: Data & Analytics Manager | D19: Mr. Ronaldo RAMIREZ RODRIGUEZ | F19: =IF(OR(B19="",E19=""),"",E19-TODAY()) | G19: =IF(B19="","",IF(E19="","Date TBC",IF(E19<TODAY(),"Departed",IF(E19-TODAY()<=14,"Due ≤ 14 days",IF(E19-TODAY()<=30,"Due ≤ 30 days","Upcoming"))))) -> Date TBC | H19: =IF(OR(B19="",D19=""),"",IF(D19="New position","New position",IF(COUNTIF('BoM Sheet'!$B$9:$B$108,"*"&D19)=0,"Not on BoM list",IF(_xlfn.MAXIFS('BoM Sheet'!$E$9:$E$108,'BoM Sheet'!$B$9:$B$108,"*"&D19)=0,"Date TBC",_xlfn.MAXIFS('BoM Sheet'!$E$9:$E$108,'BoM Sheet'!$B$9:$B$108,"*"&D19))))) -> 46216 | I19: =IF(AND(ISNUMBER(E19),ISNUMBER(H19)),E19-H19,"")
A20: =IF(B20="","",COUNTA($B$9:B20)) -> 12 | B20: Mickael PAYET | C20: First Aid and Prehospital Emergency Care Delegate | D20: Mr. Andrew MOK YUAN MIN | E20: 46234 | F20: =IF(OR(B20="",E20=""),"",E20-TODAY()) -> -90 | G20: =IF(B20="","",IF(E20="","Date TBC",IF(E20<TODAY(),"Departed",IF(E20-TODAY()<=14,"Due ≤ 14 days",IF(E20-TODAY()<=30,"Due ≤ 30 days","Upcoming"))))) -> Departed | H20: =IF(OR(B20="",D20=""),"",IF(D20="New position","New position",IF(COUNTIF('BoM Sheet'!$B$9:$B$108,"*"&D20)=0,"Not on BoM list",IF(_xlfn.MAXIFS('BoM Sheet'!$E$9:$E$108,'BoM Sheet'!$B$9:$B$108,"*"&D20)=0,"Date TBC",_xlfn.MAXIFS('BoM Sheet'!$E$9:$E$108,'BoM Sheet'!$B$9:$B$108,"*"&D20))))) -> 46228 | I20: =IF(AND(ISNUMBER(E20),ISNUMBER(H20)),E20-H20,"") -> 6
A21: =IF(B21="","",COUNTA($B$9:B21)) -> 13 | B21: Hamed MAHAMAT TAHER HAROUNA | C21: Health Delegate North | D21: Mr. Chawki LAATAR | E21: 46232 | F21: =IF(OR(B21="",E21=""),"",E21-TODAY()) -> -92 | G21: =IF(B21="","",IF(E21="","Date TBC",IF(E21<TODAY(),"Departed",IF(E21-TODAY()<=14,"Due ≤ 14 days",IF(E21-TODAY()<=30,"Due ≤ 30 days","Upcoming"))))) -> Departed | H21: =IF(OR(B21="",D21=""),"",IF(D21="New position","New position",IF(COUNTIF('BoM Sheet'!$B$9:$B$108,"*"&D21)=0,"Not on BoM list",IF(_xlfn.MAXIFS('BoM Sheet'!$E$9:$E$108,'BoM Sheet'!$B$9:$B$108,"*"&D21)=0,"Date TBC",_xlfn.MAXIFS('BoM Sheet'!$E$9:$E$108,'BoM Sheet'!$B$9:$B$108,"*"&D21))))) -> 46223 | I21: =IF(AND(ISNUMBER(E21),ISNUMBER(H21)),E21-H21,"") -> 9
A22: =IF(B22="","",COUNTA($B$9:B22)) -> 14 | B22: Jean Paul Kevin Etame | C22: Supply Chain Coordinator | D22: Mr. Abdul Basir SALEHEE | E22: 46470 | F22: =IF(OR(B22="",E22=""),"",E22-TODAY()) -> 146 | G22: =IF(B22="","",IF(E22="","Date TBC",IF(E22<TODAY(),"Departed",IF(E22-TODAY()<=14,"Due ≤ 14 days",IF(E22-TODAY()<=30,"Due ≤ 30 days","Upcoming"))))) -> Upcoming | H22: =IF(OR(B22="",D22=""),"",IF(D22="New position","New position",IF(COUNTIF('BoM Sheet'!$B$9:$B$108,"*"&D22)=0,"Not on BoM list",IF(_xlfn.MAXIFS('BoM Sheet'!$E$9:$E$108,'BoM Sheet'!$B$9:$B$108,"*"&D22)=0,"Date TBC",_xlfn.MAXIFS('BoM Sheet'!$E$9:$E$108,'BoM Sheet'!$B$9:$B$108,"*"&D22))))) -> 46470 | I22: =IF(AND(ISNUMBER(E22),ISNUMBER(H22)),E22-H22,"") -> 0
A23: =IF(B23="","",COUNTA($B$9:B23)) -> 15 | B23: Angeline Davies | C23: Head of Support | D23: Mr. Christoph KOHLER | E23: 46281 | F23: =IF(OR(B23="",E23=""),"",E23-TODAY()) -> -43 | G23: =IF(B23="","",IF(E23="","Date TBC",IF(E23<TODAY(),"Departed",IF(E23-TODAY()<=14,"Due ≤ 14 days",IF(E23-TODAY()<=30,"Due ≤ 30 days","Upcoming"))))) -> Departed | H23: =IF(OR(B23="",D23=""),"",IF(D23="New position","New position",IF(COUNTIF('BoM Sheet'!$B$9:$B$108,"*"&D23)=0,"Not on BoM list",IF(_xlfn.MAXIFS('BoM Sheet'!$E$9:$E$108,'BoM Sheet'!$B$9:$B$108,"*"&D23)=0,"Date TBC",_xlfn.MAXIFS('BoM Sheet'!$E$9:$E$108,'BoM Sheet'!$B$9:$B$108,"*"&D23))))) -> 46266 | I23: =IF(AND(ISNUMBER(E23),ISNUMBER(H23)),E23-H23,"") -> 15
A24: =IF(B24="","",COUNTA($B$9:B24)) -> 16 | B24: Mari Fungirayi MANYARARA | C24: Economic Security Delegate | D24: Ms. Cornelia Isabella HEINE | E24: 46257 | F24: =IF(OR(B24="",E24=""),"",E24-TODAY()) -> -67 | G24: =IF(B24="","",IF(E24="","Date TBC",IF(E24<TODAY(),"Departed",IF(E24-TODAY()<=14,"Due ≤ 14 days",IF(E24-TODAY()<=30,"Due ≤ 30 days","Upcoming"))))) -> Departed | H24: =IF(OR(B24="",D24=""),"",IF(D24="New position","New position",IF(COUNTIF('BoM Sheet'!$B$9:$B$108,"*"&D24)=0,"Not on BoM list",IF(_xlfn.MAXIFS('BoM Sheet'!$E$9:$E$108,'BoM Sheet'!$B$9:$B$108,"*"&D24)=0,"Date TBC",_xlfn.MAXIFS('BoM Sheet'!$E$9:$E$108,'BoM Sheet'!$B$9:$B$108,"*"&D24))))) -> 46257 | I24: =IF(AND(ISNUMBER(E24),ISNUMBER(H24)),E24-H24,"") -> 0
A25: =IF(B25="","",COUNTA($B$9:B25)) -> 17 | B25: Ferdinand DEMBELE | C25: Health Coordinator | D25: Ms. Karin LEVENBY BOVY | E25: 46314 | F25: =IF(OR(B25="",E25=""),"",E25-TODAY()) -> -10 | G25: =IF(B25="","",IF(E25="","Date TBC",IF(E25<TODAY(),"Departed",IF(E25-TODAY()<=14,"Due ≤ 14 days",IF(E25-TODAY()<=30,"Due ≤ 30 days","Upcoming"))))) -> Departed | H25: =IF(OR(B25="",D25=""),"",IF(D25="New position","New position",IF(COUNTIF('BoM Sheet'!$B$9:$B$108,"*"&D25)=0,"Not on BoM list",IF(_xlfn.MAXIFS('BoM Sheet'!$E$9:$E$108,'BoM Sheet'!$B$9:$B$108,"*"&D25)=0,"Date TBC",_xlfn.MAXIFS('BoM Sheet'!$E$9:$E$108,'BoM Sheet'!$B$9:$B$108,"*"&D25))))) -> 46314 | I25: =IF(AND(ISNUMBER(E25),ISNUMBER(H25)),E25-H25,"") -> 0
A26: =IF(B26="","",COUNTA($B$9:B26)) -> 18 | B26: Mohammed ESHAG SALIH ADAM | C26: Protection Delegate | E26: 46387 | F26: =IF(OR(B26="",E26=""),"",E26-TODAY()) -> 63 | G26: =IF(B26="","",IF(E26="","Date TBC",IF(E26<TODAY(),"Departed",IF(E26-TODAY()<=14,"Due ≤ 14 days",IF(E26-TODAY()<=30,"Due ≤ 30 days","Upcoming"))))) -> Upcoming | H26: =IF(OR(B26="",D26=""),"",IF(D26="New position","New position",IF(COUNTIF('BoM Sheet'!$B$9:$B$108,"*"&D26)=0,"Not on BoM list",IF(_xlfn.MAXIFS('BoM Sheet'!$E$9:$E$108,'BoM Sheet'!$B$9:$B$108,"*"&D26)=0,"Date TBC",_xlfn.MAXIFS('BoM Sheet'!$E$9:$E$108,'BoM Sheet'!$B$9:$B$108,"*"&D26))))) | I26: =IF(AND(ISNUMBER(E26),ISNUMBER(H26)),E26-H26,"")
A27: =IF(B27="","",COUNTA($B$9:B27)) -> 19 | B27: Tatjana HALPAAP | C27: Deputy Protection Coordinator PFL | D27: Mr. Odoardo GIRARDI | E27: 46284 | F27: =IF(OR(B27="",E27=""),"",E27-TODAY()) -> -40 | G27: =IF(B27="","",IF(E27="","Date TBC",IF(E27<TODAY(),"Departed",IF(E27-TODAY()<=14,"Due ≤ 14 days",IF(E27-TODAY()<=30,"Due ≤ 30 days","Upcoming"))))) -> Departed | H27: =IF(OR(B27="",D27=""),"",IF(D27="New position","New position",IF(COUNTIF('BoM Sheet'!$B$9:$B$108,"*"&D27)=0,"Not on BoM list",IF(_xlfn.MAXIFS('BoM Sheet'!$E$9:$E$108,'BoM Sheet'!$B$9:$B$108,"*"&D27)=0,"Date TBC",_xlfn.MAXIFS('BoM Sheet'!$E$9:$E$108,'BoM Sheet'!$B$9:$B$108,"*"&D27))))) -> 46272 | I27: =IF(AND(ISNUMBER(E27),ISNUMBER(H27)),E27-H27,"") -> 12
A28: =IF(B28="","",COUNTA($B$9:B28)) -> 20 | B28: Fernando Ivan SANTOS OSTROWSKI | C28: Deputy Coordinator Detention | D28: Mr. Martin RYNES | E28: 46328 | F28: =IF(OR(B28="",E28=""),"",E28-TODAY()) -> 4 | G28: =IF(B28="","",IF(E28="","Date TBC",IF(E28<TODAY(),"Departed",IF(E28-TODAY()<=14,"Due ≤ 14 days",IF(E28-TODAY()<=30,"Due ≤ 30 days","Upcoming"))))) -> Due ≤ 14 days | H28: =IF(OR(B28="",D28=""),"",IF(D28="New position","New position",IF(COUNTIF('BoM Sheet'!$B$9:$B$108,"*"&D28)=0,"Not on BoM list",IF(_xlfn.MAXIFS('BoM Sheet'!$E$9:$E$108,'BoM Sheet'!$B$9:$B$108,"*"&D28)=0,"Date TBC",_xlfn.MAXIFS('BoM Sheet'!$E$9:$E$108,'BoM Sheet'!$B$9:$B$108,"*"&D28))))) -> 46328 | I28: =IF(AND(ISNUMBER(E28),ISNUMBER(H28)),E28-H28,"") -> 0
A29: =IF(B29="","",COUNTA($B$9:B29)) -> 21 | B29: Hossein Javadian | C29: Country Procurement Manager | D29: Ms. Asvat AKHMEDOVA | E29: 46313 | F29: =IF(OR(B29="",E29=""),"",E29-TODAY()) -> -11 | G29: =IF(B29="","",IF(E29="","Date TBC",IF(E29<TODAY(),"Departed",IF(E29-TODAY()<=14,"Due ≤ 14 days",IF(E29-TODAY()<=30,"Due ≤ 30 days","Upcoming"))))) -> Departed | H29: =IF(OR(B29="",D29=""),"",IF(D29="New position","New position",IF(COUNTIF('BoM Sheet'!$B$9:$B$108,"*"&D29)=0,"Not on BoM list",IF(_xlfn.MAXIFS('BoM Sheet'!$E$9:$E$108,'BoM Sheet'!$B$9:$B$108,"*"&D29)=0,"Date TBC",_xlfn.MAXIFS('BoM Sheet'!$E$9:$E$108,'BoM Sheet'!$B$9:$B$108,"*"&D29))))) -> 46313 | I29: =IF(AND(ISNUMBER(E29),ISNUMBER(H29)),E29-H29,"") -> 0
A30: =IF(B30="","",COUNTA($B$9:B30)) -> 22 | B30: Els GOOSSENS | C30: Protection Delegate | D30: Vera Regina Nastassia KEGEL | E30: 46398 | F30: =IF(OR(B30="",E30=""),"",E30-TODAY()) -> 74 | G30: =IF(B30="","",IF(E30="","Date TBC",IF(E30<TODAY(),"Departed",IF(E30-TODAY()<=14,"Due ≤ 14 days",IF(E30-TODAY()<=30,"Due ≤ 30 days","Upcoming"))))) -> Upcoming | H30: =IF(OR(B30="",D30=""),"",IF(D30="New position","New position",IF(COUNTIF('BoM Sheet'!$B$9:$B$108,"*"&D30)=0,"Not on BoM list",IF(_xlfn.MAXIFS('BoM Sheet'!$E$9:$E$108,'BoM Sheet'!$B$9:$B$108,"*"&D30)=0,"Date TBC",_xlfn.MAXIFS('BoM Sheet'!$E$9:$E$108,'BoM Sheet'!$B$9:$B$108,"*"&D30))))) -> 46398 | I30: =IF(AND(ISNUMBER(E30),ISNUMBER(H30)),E30-H30,"") -> 0
A31: =IF(B31="","",COUNTA($B$9:B31)) -> 23 | B31: Nassarular Dar | C31: Detention Doctor | E31: 46371 | F31: =IF(OR(B31="",E31=""),"",E31-TODAY()) -> 47 | G31: =IF(B31="","",IF(E31="","Date TBC",IF(E31<TODAY(),"Departed",IF(E31-TODAY()<=14,"Due ≤ 14 days",IF(E31-TODAY()<=30,"Due ≤ 30 days","Upcoming"))))) -> Upcoming | H31: =IF(OR(B31="",D31=""),"",IF(D31="New position","New position",IF(COUNTIF('BoM Sheet'!$B$9:$B$108,"*"&D31)=0,"Not on BoM list",IF(_xlfn.MAXIFS('BoM Sheet'!$E$9:$E$108,'BoM Sheet'!$B$9:$B$108,"*"&D31)=0,"Date TBC",_xlfn.MAXIFS('BoM Sheet'!$E$9:$E$108,'BoM Sheet'!$B$9:$B$108,"*"&D31))))) | I31: =IF(AND(ISNUMBER(E31),ISNUMBER(H31)),E31-H31,"")
A32: =IF(B32="","",COUNTA($B$9:B32)) | F32: =IF(OR(B32="",E32=""),"",E32-TODAY()) | G32: =IF(B32="","",IF(E32="","Date TBC",IF(E32<TODAY(),"Departed",IF(E32-TODAY()<=14,"Due ≤ 14 days",IF(E32-TODAY()<=30,"Due ≤ 30 days","Upcoming"))))) | H32: =IF(OR(B32="",D32=""),"",IF(D32="New position","New position",IF(COUNTIF('BoM Sheet'!$B$9:$B$108,"*"&D32)=0,"Not on BoM list",IF(_xlfn.MAXIFS('BoM Sheet'!$E$9:$E$108,'BoM Sheet'!$B$9:$B$108,"*"&D32)=0,"Date TBC",_xlfn.MAXIFS('BoM Sheet'!$E$9:$E$108,'BoM Sheet'!$B$9:$B$108,"*"&D32))))) | I32: =IF(AND(ISNUMBER(E32),ISNUMBER(H32)),E32-H32,"")
A33: =IF(B33="","",COUNTA($B$9:B33)) | F33: =IF(OR(B33="",E33=""),"",E33-TODAY()) | G33: =IF(B33="","",IF(E33="","Date TBC",IF(E33<TODAY(),"Departed",IF(E33-TODAY()<=14,"Due ≤ 14 days",IF(E33-TODAY()<=30,"Due ≤ 30 days","Upcoming"))))) | H33: =IF(OR(B33="",D33=""),"",IF(D33="New position","New position",IF(COUNTIF('BoM Sheet'!$B$9:$B$108,"*"&D33)=0,"Not on BoM list",IF(_xlfn.MAXIFS('BoM Sheet'!$E$9:$E$108,'BoM Sheet'!$B$9:$B$108,"*"&D33)=0,"Date TBC",_xlfn.MAXIFS('BoM Sheet'!$E$9:$E$108,'BoM Sheet'!$B$9:$B$108,"*"&D33))))) | I33: =IF(AND(ISNUMBER(E33),ISNUMBER(H33)),E33-H33,"")
A34: =IF(B34="","",COUNTA($B$9:B34)) | F34: =IF(OR(B34="",E34=""),"",E34-TODAY()) | G34: =IF(B34="","",IF(E34="","Date TBC",IF(E34<TODAY(),"Departed",IF(E34-TODAY()<=14,"Due ≤ 14 days",IF(E34-TODAY()<=30,"Due ≤ 30 days","Upcoming"))))) | H34: =IF(OR(B34="",D34=""),"",IF(D34="New position","New position",IF(COUNTIF('BoM Sheet'!$B$9:$B$108,"*"&D34)=0,"Not on BoM list",IF(_xlfn.MAXIFS('BoM Sheet'!$E$9:$E$108,'BoM Sheet'!$B$9:$B$108,"*"&D34)=0,"Date TBC",_xlfn.MAXIFS('BoM Sheet'!$E$9:$E$108,'BoM Sheet'!$B$9:$B$108,"*"&D34))))) | I34: =IF(AND(ISNUMBER(E34),ISNUMBER(H34)),E34-H34,"")
A35: =IF(B35="","",COUNTA($B$9:B35)) | F35: =IF(OR(B35="",E35=""),"",E35-TODAY()) | G35: =IF(B35="","",IF(E35="","Date TBC",IF(E35<TODAY(),"Departed",IF(E35-TODAY()<=14,"Due ≤ 14 days",IF(E35-TODAY()<=30,"Due ≤ 30 days","Upcoming"))))) | H35: =IF(OR(B35="",D35=""),"",IF(D35="New position","New position",IF(COUNTIF('BoM Sheet'!$B$9:$B$108,"*"&D35)=0,"Not on BoM list",IF(_xlfn.MAXIFS('BoM Sheet'!$E$9:$E$108,'BoM Sheet'!$B$9:$B$108,"*"&D35)=0,"Date TBC",_xlfn.MAXIFS('BoM Sheet'!$E$9:$E$108,'BoM Sheet'!$B$9:$B$108,"*"&D35))))) | I35: =IF(AND(ISNUMBER(E35),ISNUMBER(H35)),E35-H35,"")
A36: =IF(B36="","",COUNTA($B$9:B36)) | F36: =IF(OR(B36="",E36=""),"",E36-TODAY()) | G36: =IF(B36="","",IF(E36="","Date TBC",IF(E36<TODAY(),"Departed",IF(E36-TODAY()<=14,"Due ≤ 14 days",IF(E36-TODAY()<=30,"Due ≤ 30 days","Upcoming"))))) | H36: =IF(OR(B36="",D36=""),"",IF(D36="New position","New position",IF(COUNTIF('BoM Sheet'!$B$9:$B$108,"*"&D36)=0,"Not on BoM list",IF(_xlfn.MAXIFS('BoM Sheet'!$E$9:$E$108,'BoM Sheet'!$B$9:$B$108,"*"&D36)=0,"Date TBC",_xlfn.MAXIFS('BoM Sheet'!$E$9:$E$108,'BoM Sheet'!$B$9:$B$108,"*"&D36))))) | I36: =IF(AND(ISNUMBER(E36),ISNUMBER(H36)),E36-H36,"")
A37: =IF(B37="","",COUNTA($B$9:B37)) | F37: =IF(OR(B37="",E37=""),"",E37-TODAY()) | G37: =IF(B37="","",IF(E37="","Date TBC",IF(E37<TODAY(),"Departed",IF(E37-TODAY()<=14,"Due ≤ 14 days",IF(E37-TODAY()<=30,"Due ≤ 30 days","Upcoming"))))) | H37: =IF(OR(B37="",D37=""),"",IF(D37="New position","New position",IF(COUNTIF('BoM Sheet'!$B$9:$B$108,"*"&D37)=0,"Not on BoM list",IF(_xlfn.MAXIFS('BoM Sheet'!$E$9:$E$108,'BoM Sheet'!$B$9:$B$108,"*"&D37)=0,"Date TBC",_xlfn.MAXIFS('BoM Sheet'!$E$9:$E$108,'BoM Sheet'!$B$9:$B$108,"*"&D37))))) | I37: =IF(AND(ISNUMBER(E37),ISNUMBER(H37)),E37-H37,"")
A38: =IF(B38="","",COUNTA($B$9:B38)) | F38: =IF(OR(B38="",E38=""),"",E38-TODAY()) | G38: =IF(B38="","",IF(E38="","Date TBC",IF(E38<TODAY(),"Departed",IF(E38-TODAY()<=14,"Due ≤ 14 days",IF(E38-TODAY()<=30,"Due ≤ 30 days","Upcoming"))))) | H38: =IF(OR(B38="",D38=""),"",IF(D38="New position","New position",IF(COUNTIF('BoM Sheet'!$B$9:$B$108,"*"&D38)=0,"Not on BoM list",IF(_xlfn.MAXIFS('BoM Sheet'!$E$9:$E$108,'BoM Sheet'!$B$9:$B$108,"*"&D38)=0,"Date TBC",_xlfn.MAXIFS('BoM Sheet'!$E$9:$E$108,'BoM Sheet'!$B$9:$B$108,"*"&D38))))) | I38: =IF(AND(ISNUMBER(E38),ISNUMBER(H38)),E38-H38,"")
A39: =IF(B39="","",COUNTA($B$9:B39)) | F39: =IF(OR(B39="",E39=""),"",E39-TODAY()) | G39: =IF(B39="","",IF(E39="","Date TBC",IF(E39<TODAY(),"Departed",IF(E39-TODAY()<=14,"Due ≤ 14 days",IF(E39-TODAY()<=30,"Due ≤ 30 days","Upcoming"))))) | H39: =IF(OR(B39="",D39=""),"",IF(D39="New position","New position",IF(COUNTIF('BoM Sheet'!$B$9:$B$108,"*"&D39)=0,"Not on BoM list",IF(_xlfn.MAXIFS('BoM Sheet'!$E$9:$E$108,'BoM Sheet'!$B$9:$B$108,"*"&D39)=0,"Date TBC",_xlfn.MAXIFS('BoM Sheet'!$E$9:$E$108,'BoM Sheet'!$B$9:$B$108,"*"&D39))))) | I39: =IF(AND(ISNUMBER(E39),ISNUMBER(H39)),E39-H39,"")
A40: =IF(B40="","",COUNTA($B$9:B40)) | F40: =IF(OR(B40="",E40=""),"",E40-TODAY()) | G40: =IF(B40="","",IF(E40="","Date TBC",IF(E40<TODAY(),"Departed",IF(E40-TODAY()<=14,"Due ≤ 14 days",IF(E40-TODAY()<=30,"Due ≤ 30 days","Upcoming"))))) | H40: =IF(OR(B40="",D40=""),"",IF(D40="New position","New position",IF(COUNTIF('BoM Sheet'!$B$9:$B$108,"*"&D40)=0,"Not on BoM list",IF(_xlfn.MAXIFS('BoM Sheet'!$E$9:$E$108,'BoM Sheet'!$B$9:$B$108,"*"&D40)=0,"Date TBC",_xlfn.MAXIFS('BoM Sheet'!$E$9:$E$108,'BoM Sheet'!$B$9:$B$108,"*"&D40))))) | I40: =IF(AND(ISNUMBER(E40),ISNUMBER(H40)),E40-H40,"")
A41: =IF(B41="","",COUNTA($B$9:B41)) | F41: =IF(OR(B41="",E41=""),"",E41-TODAY()) | G41: =IF(B41="","",IF(E41="","Date TBC",IF(E41<TODAY(),"Departed",IF(E41-TODAY()<=14,"Due ≤ 14 days",IF(E41-TODAY()<=30,"Due ≤ 30 days","Upcoming"))))) | H41: =IF(OR(B41="",D41=""),"",IF(D41="New position","New position",IF(COUNTIF('BoM Sheet'!$B$9:$B$108,"*"&D41)=0,"Not on BoM list",IF(_xlfn.MAXIFS('BoM Sheet'!$E$9:$E$108,'BoM Sheet'!$B$9:$B$108,"*"&D41)=0,"Date TBC",_xlfn.MAXIFS('BoM Sheet'!$E$9:$E$108,'BoM Sheet'!$B$9:$B$108,"*"&D41))))) | I41: =IF(AND(ISNUMBER(E41),ISNUMBER(H41)),E41-H41,"")
A42: =IF(B42="","",COUNTA($B$9:B42)) | F42: =IF(OR(B42="",E42=""),"",E42-TODAY()) | G42: =IF(B42="","",IF(E42="","Date TBC",IF(E42<TODAY(),"Departed",IF(E42-TODAY()<=14,"Due ≤ 14 days",IF(E42-TODAY()<=30,"Due ≤ 30 days","Upcoming"))))) | H42: =IF(OR(B42="",D42=""),"",IF(D42="New position","New position",IF(COUNTIF('BoM Sheet'!$B$9:$B$108,"*"&D42)=0,"Not on BoM list",IF(_xlfn.MAXIFS('BoM Sheet'!$E$9:$E$108,'BoM Sheet'!$B$9:$B$108,"*"&D42)=0,"Date TBC",_xlfn.MAXIFS('BoM Sheet'!$E$9:$E$108,'BoM Sheet'!$B$9:$B$108,"*"&D42))))) | I42: =IF(AND(ISNUMBER(E42),ISNUMBER(H42)),E42-H42,"")
A43: =IF(B43="","",COUNTA($B$9:B43)) | F43: =IF(OR(B43="",E43=""),"",E43-TODAY()) | G43: =IF(B43="","",IF(E43="","Date TBC",IF(E43<TODAY(),"Departed",IF(E43-TODAY()<=14,"Due ≤ 14 days",IF(E43-TODAY()<=30,"Due ≤ 30 days","Upcoming"))))) | H43: =IF(OR(B43="",D43=""),"",IF(D43="New position","New position",IF(COUNTIF('BoM Sheet'!$B$9:$B$108,"*"&D43)=0,"Not on BoM list",IF(_xlfn.MAXIFS('BoM Sheet'!$E$9:$E$108,'BoM Sheet'!$B$9:$B$108,"*"&D43)=0,"Date TBC",_xlfn.MAXIFS('BoM Sheet'!$E$9:$E$108,'BoM Sheet'!$B$9:$B$108,"*"&D43))))) | I43: =IF(AND(ISNUMBER(E43),ISNUMBER(H43)),E43-H43,"")
...

Sheet Summary
A1: BoM / EoM Summary
A2: Arrivals and departures per month, updated from the BoM and EoM sheets
B4: Month | C4: Arrivals (BoM) | D4: Departures (EoM) | E4: Net change | G4: How it works
B5: 46023 | C5: =COUNTIFS('BoM Sheet'!$E$9:$E$108,">="&B5,'BoM Sheet'!$E$9:$E$108,"<"&EDATE(B5,1)) -> 0 | D5: =COUNTIFS('EoM Sheet'!$E$9:$E$108,">="&B5,'EoM Sheet'!$E$9:$E$108,"<"&EDATE(B5,1)) -> 0 | E5: =C5-D5 -> 0 | G5: • Type names, positions and dates only — numbering, status, days to go and handover columns fill in by themselves. • Status changes automatically every day based on today's date. • Handover overlap compares the BoM and EoM sheets by name: keep the outgoing person's name in the BoM 'Replacing' column identical to the EoM 'Name' column (titles like Mr./Ms. go in the BoM name only). • Negative overlap (red) = days the post will be vacant between departure and arrival. • Dates outside the months above are still tracked on the BoM/EoM sheets.
B6: 46054 | C6: =COUNTIFS('BoM Sheet'!$E$9:$E$108,">="&B6,'BoM Sheet'!$E$9:$E$108,"<"&EDATE(B6,1)) -> 0 | D6: =COUNTIFS('EoM Sheet'!$E$9:$E$108,">="&B6,'EoM Sheet'!$E$9:$E$108,"<"&EDATE(B6,1)) -> 0 | E6: =C6-D6 -> 0
B7: 46082 | C7: =COUNTIFS('BoM Sheet'!$E$9:$E$108,">="&B7,'BoM Sheet'!$E$9:$E$108,"<"&EDATE(B7,1)) -> 0 | D7: =COUNTIFS('EoM Sheet'!$E$9:$E$108,">="&B7,'EoM Sheet'!$E$9:$E$108,"<"&EDATE(B7,1)) -> 0 | E7: =C7-D7 -> 0
B8: 46113 | C8: =COUNTIFS('BoM Sheet'!$E$9:$E$108,">="&B8,'BoM Sheet'!$E$9:$E$108,"<"&EDATE(B8,1)) -> 3 | D8: =COUNTIFS('EoM Sheet'!$E$9:$E$108,">="&B8,'EoM Sheet'!$E$9:$E$108,"<"&EDATE(B8,1)) -> 0 | E8: =C8-D8 -> 3
B9: 46143 | C9: =COUNTIFS('BoM Sheet'!$E$9:$E$108,">="&B9,'BoM Sheet'!$E$9:$E$108,"<"&EDATE(B9,1)) -> 2 | D9: =COUNTIFS('EoM Sheet'!$E$9:$E$108,">="&B9,'EoM Sheet'!$E$9:$E$108,"<"&EDATE(B9,1)) -> 0 | E9: =C9-D9 -> 2
B10: 46174 | C10: =COUNTIFS('BoM Sheet'!$E$9:$E$108,">="&B10,'BoM Sheet'!$E$9:$E$108,"<"&EDATE(B10,1)) -> 1 | D10: =COUNTIFS('EoM Sheet'!$E$9:$E$108,">="&B10,'EoM Sheet'!$E$9:$E$108,"<"&EDATE(B10,1)) -> 2 | E10: =C10-D10 -> -1
B11: 46204 | C11: =COUNTIFS('BoM Sheet'!$E$9:$E$108,">="&B11,'BoM Sheet'!$E$9:$E$108,"<"&EDATE(B11,1)) -> 4 | D11: =COUNTIFS('EoM Sheet'!$E$9:$E$108,">="&B11,'EoM Sheet'!$E$9:$E$108,"<"&EDATE(B11,1)) -> 2 | E11: =C11-D11 -> 2
B12: 46235 | C12: =COUNTIFS('BoM Sheet'!$E$9:$E$108,">="&B12,'BoM Sheet'!$E$9:$E$108,"<"&EDATE(B12,1)) -> 2 | D12: =COUNTIFS('EoM Sheet'!$E$9:$E$108,">="&B12,'EoM Sheet'!$E$9:$E$108,"<"&EDATE(B12,1)) -> 2 | E12: =C12-D12 -> 0
B13: 46266 | C13: =COUNTIFS('BoM Sheet'!$E$9:$E$108,">="&B13,'BoM Sheet'!$E$9:$E$108,"<"&EDATE(B13,1)) -> 3 | D13: =COUNTIFS('EoM Sheet'!$E$9:$E$108,">="&B13,'EoM Sheet'!$E$9:$E$108,"<"&EDATE(B13,1)) -> 2 | E13: =C13-D13 -> 1
B14: 46296 | C14: =COUNTIFS('BoM Sheet'!$E$9:$E$108,">="&B14,'BoM Sheet'!$E$9:$E$108,"<"&EDATE(B14,1)) -> 3 | D14: =COUNTIFS('EoM Sheet'!$E$9:$E$108,">="&B14,'EoM Sheet'!$E$9:$E$108,"<"&EDATE(B14,1)) -> 2 | E14: =C14-D14 -> 1
B15: 46327 | C15: =COUNTIFS('BoM Sheet'!$E$9:$E$108,">="&B15,'BoM Sheet'!$E$9:$E$108,"<"&EDATE(B15,1)) -> 1 | D15: =COUNTIFS('EoM Sheet'!$E$9:$E$108,">="&B15,'EoM Sheet'!$E$9:$E$108,"<"&EDATE(B15,1)) -> 1 | E15: =C15-D15 -> 0
B16: 46357 | C16: =COUNTIFS('BoM Sheet'!$E$9:$E$108,">="&B16,'BoM Sheet'!$E$9:$E$108,"<"&EDATE(B16,1)) -> 1 | D16: =COUNTIFS('EoM Sheet'!$E$9:$E$108,">="&B16,'EoM Sheet'!$E$9:$E$108,"<"&EDATE(B16,1)) -> 2 | E16: =C16-D16 -> -1
B17: 46388 | C17: =COUNTIFS('BoM Sheet'!$E$9:$E$108,">="&B17,'BoM Sheet'!$E$9:$E$108,"<"&EDATE(B17,1)) -> 1 | D17: =COUNTIFS('EoM Sheet'!$E$9:$E$108,">="&B17,'EoM Sheet'!$E$9:$E$108,"<"&EDATE(B17,1)) -> 1 | E17: =C17-D17 -> 0
... B28: 46722 | C28: =COUNTIFS('BoM Sheet'!$E$9:$E$108,">="&B28,'BoM Sheet'!$E$9:$E$108,"<"&EDATE(B28,1)) -> 0 | D28: =COUNTIFS('EoM Sheet'!$E$9:$E$108,">="&B28,'EoM Sheet'!$E$9:$E$108,"<"&EDATE(B28,1)) -> 0 | E28: =C28-D28 -> 0
B29: Total | C29: =SUM(C5:C28) -> 22 | D29: =SUM(D5:D28) -> 15 | E29: =SUM(E5:E28) -> 7
